ERROR:root:main exception - 2016-11-30 18:59:24.394124
Traceback (most recent call last):
  File "idaweb_scraper.py", line 164, in <module>
    driver.find_element_by_xpath("//input[@value='Select all']").click()
  File "/home/ema/anaconda3/lib/python3.5/site-packages/selenium/webdriver/remote/webdriver.py", line 293, in find_element_by_xpath
    return self.find_element(by=By.XPATH, value=xpath)
  File "/home/ema/anaconda3/lib/python3.5/site-packages/selenium/webdriver/remote/webdriver.py", line 752, in find_element
    'value': value})['value']
  File "/home/ema/anaconda3/lib/python3.5/site-packages/selenium/webdriver/remote/webdriver.py", line 236, in execute
    self.error_handler.check_response(response)
  File "/home/ema/anaconda3/lib/python3.5/site-packages/selenium/webdriver/remote/errorhandler.py", line 192, in check_response
    raise exception_class(message, screen, stacktrace)
selenium.common.exceptions.NoSuchElementException: Message: no such element: Unable to locate element: {"method":"xpath","selector":"//input[@value='Select all']"}
  (Session info: chrome=53.0.2785.116)
  (Driver info: chromedriver=2.22.397932 (282ed7cf89cf0053b6542e0d0f039d4123bbb6ad),platform=Linux 4.4.0-38-generic x86_64)

